{
    "registryname": "darkness-collector",
    "localizedname": "暗影凝聚器",
    "requires-blueprint": true,
    "color": "34c7bd",
    "modifiers": [
        {
            "x": 0,
            "y": 2,
            "z": 4,
            "elements": "environmentaltech:aethium@0",
            "description": "将块放置在后部电路上方，以将所需时间减半",
            "modifier": {
                "io": "input",
                "target": "duration",
                "operation": 1,
                "multiplier": 0.5
            }
        },
        {
            "x": 2,
            "y": 2,
            "z": 2,
            "elements":  "iceandfire:dragonsteel_ice_block@0",
            "description": "将块放置在左侧电路上方，以将所需的流体减半",
            "modifier": {
                "io": "input",
                "target": "fluid",
                "operation": 1,
                "multiplier": 0.5
            }
        },
        {
            "x": -2,
            "y": 2,
            "z": 2,
            "elements": "deepmoblearning:infused_ingot_block@0",
            "description": "将块放在右侧电路上方，有20%的机会不消耗输入",
            "modifier": {
                "io": "input",
                "target": "item",
                "operation": 0,
                "multiplier": -0.2,
                "affectChance": true
            }
        },
        {
            "x": 0,
            "y": 2,
            "z": 0,
            "elements": "thaumcraft:metal_void",
            "description": "放置在中心电路上方，2倍物品输出",
            "modifier": {
                "io": "output",
                "target": "item",
                "operation": 1,
                "multiplier": 2.0
            }
        },
        {
            "x": 0,
            "y": 2,
            "z": 0,
            "elements": "thaumadditions:mithrillium_block",
            "description": "放置在中心电路上方，3倍物品输出",
            "modifier": {
                "io": "output",
                "target": "item",
                "operation": 1,
                "multiplier": 3.0
            }
        },
        {
            "x": 0,
            "y": 2,
            "z": 0,
            "elements": "thaumadditions:adaminite_block",
            "description": "放置在中心电路上方，4倍物品输出",
            "modifier": {
                "io": "output",
                "target": "item",
                "operation": 1,
                "multiplier": 4.0
            }
        },
        {
            "x": 0,
            "y": 2,
            "z": 0,
            "elements": "thaumadditions:mithminite_block",
            "description": "放置在中心电路上方，5倍物品输出",
            "modifier": {
                "io": "output",
                "target": "item",
                "operation": 1,
                "multiplier": 5.0
            }
        }
    ],
    "parts": [
        {
            "x": 0,
            "y": 0,
            "z": 4,
            "elements": [
                "casings_item_fluid"
            ]
        },
        {
            "x": 0,
            "y": 1,
            "z": 0,
            "elements": [
                "modularmachinery:blockcasing@5"
            ]
        },
        {
            "x": 0,
            "y": 1,
            "z": 4,
            "elements": [
                "modularmachinery:blockcasing@5"
            ]
        },
        {
            "x": -2,
            "y": 0,
            "z": 2,
             "elements": [
                "casings_item_fluid"
            ]
        },
        {
            "x": 2,
            "y": 0,
            "z": 2,
            "elements": [
                "casings_item_fluid"
            ]
        },
        {
            "x": -2,
            "y": 1,
            "z": 2,
             "elements": [
                "modularmachinery:blockcasing@5"
            ]
        },
        {
            "x": 1,
            "y": 2,
            "z": 1,
            "elements": [
                "environmentaltech:structure_frame_3@0"
            ]
        },
        {
            "x": 2,
            "y": 1,
            "z": 2,
            "elements": [
                "modularmachinery:blockcasing@5"
            ]
        },
        {
            "x": -2,
            "y": 7,
            "z": 3,
            "elements": [
                "chisel:energizedvoidstone@2"
            ]
        },
        {
            "x": -1,
            "y": 5,
            "z": 2,
            "elements": [
                "chisel:energizedvoidstone@2"
            ]
        },
        {
            "x": 2,
            "y": 7,
            "z": 3,
            "elements": [
                "chisel:energizedvoidstone@2"
            ]
        },
        {
            "x": 1,
            "y": 5,
            "z": 2,
            "elements": [
                "chisel:energizedvoidstone@2"
            ]
        },
        {
            "x": 0,
            "y": 3,
            "z": 1,
            "elements": [
                "libvulpes:advstructuremachine@0"
            ]
        },
        {
            "x": -2,
            "y": 8,
            "z": 3,
            "elements": [
                "fossil:obsidian_spikes@0"
            ]
        },
        {
            "x": -2,
            "y": 6,
            "z": 2,
            "elements": [
                "chisel:energizedvoidstone@2"
            ]
        },
        {
            "x": 2,
            "y": 8,
            "z": 3,
            "elements": [
                "fossil:obsidian_spikes@0"
            ]
        },
        {
            "x": 0,
            "y": 4,
            "z": 1,
            "elements": [
                "chisel:energizedvoidstone@2"
            ]
        },
        {
            "x": 2,
            "y": 6,
            "z": 2,
            "elements": [
                "chisel:energizedvoidstone@2"
            ]
        },
        {
            "x": -1,
            "y": 0,
            "z": 3,
             "elements": [
                "environmentaltech:structure_frame_3@0"
            ]
        },
        {
            "x": 0,
            "y": 0,
            "z": 3,
            "elements": [
                "enderio:block_alloy_endergy@2"
            ]
        },
        {
            "x": 1,
            "y": 0,
            "z": 3,
            "elements": [
                "environmentaltech:structure_frame_3@0"
            ]
        },
        {
            "x": -3,
            "y": 7,
            "z": 2,
            "elements": [
                "chisel:energizedvoidstone@2"
            ]
        },
        {
            "x": -2,
            "y": 7,
            "z": 2,
            "elements": [
                "chisel:energizedvoidstone@2"
            ]
        },
        {
            "x": -1,
            "y": 5,
            "z": 1,
            "elements": [
                "chisel:energizedvoidstone@2"
            ]
        },
        {
            "x": 0,
            "y": 5,
            "z": 1,
            "elements": [
                "chisel:energizedvoidstone@2"
            ]
        },
        {
            "x": 2,
            "y": 7,
            "z": 2,
            "elements": [
                "chisel:energizedvoidstone@2"
            ]
        },
        {
            "x": 1,
            "y": 5,
            "z": 1,
            "elements": [
                "chisel:energizedvoidstone@2"
            ]
        },
        {
            "x": 3,
            "y": 7,
            "z": 2,
            "elements": [
                "chisel:energizedvoidstone@2"
            ]
        },
        {
            "x": -1,
            "y": 1,
            "z": 3,
            "elements": [
                "environmentaltech:structure_frame_3@0"
            ]
        },
        {
            "x": 0,
            "y": 1,
            "z": 3,
            "elements": [
                "enderio:block_fluid_ender_distillation@0"
            ]
        },
        {
            "x": 1,
            "y": 1,
            "z": 3,
            "elements": [
                "environmentaltech:structure_frame_3@0"
            ]
        },
        {
            "x": -3,
            "y": 8,
            "z": 2,
            "elements": [
                "chisel:energizedvoidstone@4"
            ]
        },
        {
            "x": -2,
            "y": 8,
            "z": 2,
            "elements": [
                "fossil:obsidian_spikes@0"
            ]
        },
        {
            "x": -2,
            "y": 6,
            "z": 1,
            "elements": [
                "chisel:energizedvoidstone@2"
            ]
        },
        {
            "x": -1,
            "y": 6,
            "z": 1,
            "elements": [
                "chisel:energizedvoidstone@2"
            ]
        },
        {
            "x": 2,
            "y": 8,
            "z": 2,
            "elements": [
                "fossil:obsidian_spikes@0"
            ]
        },
        {
            "x": 1,
            "y": 6,
            "z": 1,
            "elements": [
                "chisel:energizedvoidstone@2"
            ]
        },
        {
            "x": 3,
            "y": 8,
            "z": 2,
            "elements": [
                "chisel:energizedvoidstone@4"
            ]
        },
        {
            "x": 2,
            "y": 6,
            "z": 1,
            "elements": [
                "chisel:energizedvoidstone@2"
            ]
        },

        {
            "x": -1,
            "y": 2,
            "z": 3,
            "elements": [
                "environmentaltech:structure_frame_3@0"
            ]
        },
        {
            "x": 0,
            "y": 2,
            "z": 3,
            "elements": [
                "libvulpes:advstructuremachine@0"
            ]
        },
        {
            "x": -1,
            "y": 0,
            "z": 2,
            "elements": [
                "enderio:block_alloy_endergy@2"
            ]
        },
        {
            "x": 0,
            "y": 0,
            "z": 2,
            "elements": [
                "enderio:block_alloy_endergy@2"
            ]
        },
        {
            "x": 1,
            "y": 2,
            "z": 3,
             "elements": [
                "environmentaltech:structure_frame_3@0"
            ]
        },
        {
            "x": 1,
            "y": 0,
            "z": 2,
            "elements": [
                "enderio:block_alloy_endergy@2"
            ]
        },
        {
            "x": -2,
            "y": 7,
            "z": 1,
            "elements": [
                "chisel:energizedvoidstone@2"
            ]
        },
        {
            "x": 2,
            "y": 7,
            "z": 1,
            "elements": [
                "chisel:energizedvoidstone@2"
            ]
        },
        {
            "x": 0,
            "y": 7,
            "z": 5,
            "elements": [
                "chisel:energizedvoidstone@2"
            ]
        },

        {
            "x": 0,
            "y": 3,
            "z": 3,
            "elements": [
                "libvulpes:advstructuremachine@0"
            ]
        },
        {
            "x": -1,
            "y": 1,
            "z": 2,
            "elements": [
                "enderio:block_fluid_ender_distillation@0"
            ]
        },
        {
            "x": 0,
            "y": 1,
            "z": 2,
            "elements": [
                "enderio:block_fluid_ender_distillation@0"
            ]
        },
        {
            "x": 1,
            "y": 1,
            "z": 2,
            "elements": [
                "enderio:block_fluid_ender_distillation@0"
            ]
        },
        {
            "x": -2,
            "y": 8,
            "z": 1,
            "elements": [
                "fossil:obsidian_spikes@0"
            ]
        },
        {
            "x": -1,
            "y": 6,
            "z": 0,
            "elements": [
                "chisel:energizedvoidstone@2"
            ]
        },
        {
            "x": 0,
            "y": 6,
            "z": 0,
            "elements": [
                "chisel:energizedvoidstone@2"
            ]
        },
        {
            "x": 2,
            "y": 8,
            "z": 1,
            "elements": [
                "fossil:obsidian_spikes@0"
            ]
        },
        {
            "x": 1,
            "y": 6,
            "z": 0,
            "elements": [
                "chisel:energizedvoidstone@2"
            ]
        },
        {
            "x": -1,
            "y": 6,
            "z": 4,
            "elements": [
                "chisel:energizedvoidstone@2"
            ]
        },
        {
            "x": 0,
            "y": 8,
            "z": 5,
            "elements": [
                "chisel:energizedvoidstone@4"
            ]
        },
        {
            "x": 0,
            "y": 6,
            "z": 4,
            "elements": [
                "chisel:energizedvoidstone@2"
            ]
        },
        {
            "x": 1,
            "y": 6,
            "z": 4,
            "elements": [
                "chisel:energizedvoidstone@2"
            ]
        },
        {
            "x": 0,
            "y": 4,
            "z": 3,
            "elements": [
                "chisel:energizedvoidstone@2"
            ]
        },
        {
            "x": -1,
            "y": 2,
            "z": 2,
            "elements": [
                "libvulpes:advstructuremachine@0"
            ]
        },
        {
            "x": -1,
            "y": 0,
            "z": 1,
            "elements": [
                "environmentaltech:structure_frame_3@0"
            ]
        },
        {
            "x": 0,
            "y": 0,
            "z": 1,
            "elements": [
                "enderio:block_alloy_endergy@2"
            ]
        },
        {
            "x": 1,
            "y": 2,
            "z": 2,
            "elements": [
                "libvulpes:advstructuremachine@0"
            ]
        },
        {
            "x": 1,
            "y": 0,
            "z": 1,
            "elements": [
                "environmentaltech:structure_frame_3@0"
            ]
        },
        {
            "x": 0,
            "y": 8,
            "z": -1,
            "elements": [
                "chisel:energizedvoidstone@4"
            ]
        },
        {
            "x": -1,
            "y": 7,
            "z": 0,
            "elements": [
                "chisel:energizedvoidstone@2"
            ]
        },
        {
            "x": 0,
            "y": 7,
            "z": 0,
            "elements": [
                "chisel:energizedvoidstone@2"
            ]
        },
        {
            "x": 1,
            "y": 7,
            "z": 0,
            "elements": [
                "chisel:energizedvoidstone@2"
            ]
        },
        {
            "x": -1,
            "y": 7,
            "z": 4,
            "elements": [
                "chisel:energizedvoidstone@2"
            ]
        },
        {
            "x": -1,
            "y": 5,
            "z": 3,
            "elements": [
                "chisel:energizedvoidstone@2"
            ]
        },
        {
            "x": 0,
            "y": 7,
            "z": 4,
            "elements": [
                "chisel:energizedvoidstone@2"
            ]
        },
        {
            "x": -1,
            "y": 3,
            "z": 2,
            "elements": [
                "libvulpes:advstructuremachine@0"
            ]
        },
        {
            "x": 1,
            "y": 7,
            "z": 4,
            "elements": [
                "chisel:energizedvoidstone@2"
            ]
        },
        {
            "x": 0,
            "y": 5,
            "z": 3,
            "elements": [
                "chisel:energizedvoidstone@2"
            ]
        },
        {
            "x": 1,
            "y": 5,
            "z": 3,
            "elements": [
                "chisel:energizedvoidstone@2"
            ]
        },
        {
            "x": -1,
            "y": 1,
            "z": 1,
            "elements": [
                "environmentaltech:structure_frame_3@0"
            ]
        },
        {
            "x": 1,
            "y": 3,
            "z": 2,
            "elements": [
                "libvulpes:advstructuremachine@0"
            ]
        },
        {
            "x": 0,
            "y": 1,
            "z": 1,
            "elements": [
                "enderio:block_fluid_ender_distillation@0"
            ]
        },
        {
            "x": 1,
            "y": 1,
            "z": 1,
             "elements": [
                "environmentaltech:structure_frame_3@0"
            ]
        },
        {
            "x": 0,
            "y": 7,
            "z": -1,
            "elements": [
                "chisel:energizedvoidstone@2"
            ]
        },
        {
            "x": -1,
            "y": 8,
            "z": 0,
            "elements": [
                "fossil:obsidian_spikes@0"
            ]
        },
        {
            "x": 0,
            "y": 8,
            "z": 0,
            "elements": [
                "fossil:obsidian_spikes@0"
            ]
        },
        {
            "x": 1,
            "y": 8,
            "z": 0,
            "elements": [
                "fossil:obsidian_spikes@0"
            ]
        },
        {
            "x": -2,
            "y": 6,
            "z": 3,
            "elements": [
                "chisel:energizedvoidstone@2"
            ]
        },
        {
            "x": -1,
            "y": 8,
            "z": 4,
            "elements": [
                "fossil:obsidian_spikes@0"
            ]
        },
        {
            "x": -1,
            "y": 6,
            "z": 3,
            "elements": [
                "chisel:energizedvoidstone@2"
            ]
        },
        {
            "x": 0,
            "y": 8,
            "z": 4,
            "elements": [
                "fossil:obsidian_spikes@0"
            ]
        },
        {
            "x": -1,
            "y": 4,
            "z": 2,
            "elements": [
                "chisel:energizedvoidstone@2"
            ]
        },
        {
            "x": 1,
            "y": 8,
            "z": 4,
            "elements": [
                "fossil:obsidian_spikes@0"
            ]
        },
        {
            "x": 1,
            "y": 6,
            "z": 3,
            "elements": [
                "chisel:energizedvoidstone@2"
            ]
        },
        {
            "x": -1,
            "y": 2,
            "z": 1,
            "elements": [
                "environmentaltech:structure_frame_3@0"
            ]
        },
        {
            "x": 2,
            "y": 6,
            "z": 3,
            "elements": [
                "chisel:energizedvoidstone@2"
            ]
        },
        {
            "x": 1,
            "y": 4,
            "z": 2,
            "elements": [
                "chisel:energizedvoidstone@2"
            ]
        },
        {
            "x": 0,
            "y": 2,
            "z": 1,
            "elements": [
                "libvulpes:advstructuremachine@0"
            ]
        }
    ]}